<mujoco model="task1">
    <visual>
        <headlight ambient="0.5 0.5 0.5" />
    </visual>

    <option gravity="0 0 -9.81" />

    <worldbody>
        <light name="top" pos="0 0 1"/>
        <geom type="plane" pos="-0.5 -0.5 0" size="1 1 0.1"  rgba="0 .9 0 1"/>
        <body name="base" euler="0 0 0">
            <geom name="down_part" type="box" pos="0 0 0.1" size=".1 .05 .1" rgba="0.2 0.2 0.2 1"/>
            <geom name="sphere" pos="0 0 .2" size=".01" rgba="0.2 0.2 0.2 1"/>
            <geom name="upper_part" type="box" pos="0 0 .27" size=".07 .05 .07" rgba="0.2 0.2 0.2 0.7"/>
        </body>
        <body name="motor1" euler="0 0 0">
            <geom type="cylinder" fromto="0.1105 -.08 0.2 0.0875 -.08 0.2" size=".018" mass="0.065" rgba=".1 .1 .1 .8"/>
            <joint name="hinge_1" pos="0.099 -.08 0.2" axis="1 0 0" />
            <body name="motor2" euler="0 0 0">
                <geom type="cylinder" fromto="0.135 -.08 0.1885 0.135 -.08 0.2115" size=".018" mass="0.065" rgba=".1 .1 .1 .8"/>
                <joint name="hinge_2" pos="0.135 -.08 0.2" axis="0 0 1" />
                <body name="motor3" euler="0 0 0">
                    <geom type="cylinder" fromto="0.135 -.0555 0.2 0.135 -.0325 0.2" size=".018" mass="0.065" rgba=".1 .1 .1 .8"/>
                    <joint name="hinge_3" pos="0.135 -.0440 0.2" axis="0 1 0" />
                    <body name="link_1st" euler="0 0 0">
                        <geom name="link1" type="box" pos="0.135 .0175 0.2" size=".005 .05 .005" mass="0.02" rgba="0.2 0.5 0.2 1"/>
                        <body name="elbow1" euler="0 0 0">
                            <geom type="cylinder" fromto="0.1235 0.0855 0.2 0.1465 0.0855 0.2" size=".018" mass="0.065" rgba=".1 .1 .1 .8"/>
                            <joint name="hinge_4" pos="0.135 0.0855 0.2" axis="1 0 0" />
                            <body name="link_2" euler="0 0 0">
                                <geom name="link2" type="box" pos="0.135 0.1535 0.2" size=".005 .05 .005" mass="0.02" rgba="0.2 0.2 0.5 1"/>
                                <body name="mass_endeff" euler="0 0 0">
                                    <geom name="mass" pos="0.135 0.2235 0.2" size=".02" mass="0.02" rgba="0.5 0.2 0.2 1"/>
                                </body>
                            </body>
                        </body>
                    </body>
                </body>
            </body>
        </body>
    </worldbody>
</mujoco>